<robot name="wrist">
    <link name="world">
    </link>

    <joint name="joint_x" type="prismatic">
        <parent link="world"/>
        <child link="wrist_x"/>
        <origin rpy="0.0 0.0 0.0" xyz="0.0 0.0 0.0"/>
        <axis xyz="1 0 0"/>
        <limit lower="-1.0" upper="1.0" velocity="0.05" effort="1e9"/>
        <dynamics damping="0.0" friction="0.0"/>
    </joint>

    <link name="wrist_x">
        <inertial>
            <mass value="0.001"/>
            <inertia ixx="0.1" iyy="0.1" izz="0.1" ixy="0.0" ixz="0.0" iyz="0.0"/>
        </inertial>
    </link>

    <joint name="joint_y" type="prismatic">
        <parent link="wrist_x"/>
        <child link="wrist_y"/>
        <origin rpy="0.0 0.0 0.0" xyz="0.0 0.0 0.0"/>
        <axis xyz="0 1 0"/>
        <limit lower="-1.0" upper="1.0" velocity="0.05" effort="1e9"/>
        <dynamics damping="0.0" friction="0.0"/>
    </joint>

    <link name="wrist_y">
        <inertial>
            <mass value="0.001"/>
            <inertia ixx="0.1" iyy="0.1" izz="0.1" ixy="0.0" ixz="0.0" iyz="0.0"/>
        </inertial>
    </link>

    <joint name="joint_z" type="prismatic">
        <parent link="wrist_y"/>
        <child link="wrist_z"/>
        <origin rpy="0.0 0.0 0.0" xyz="0.0 0.0 0.0"/>
        <axis xyz="0 0 1"/>
        <limit lower="-1.0" upper="1.0" velocity="0.05" effort="1e9"/>
        <dynamics damping="0.0" friction="0.0"/>
    </joint>

    <link name="wrist_z">
        <inertial>
            <mass value="0.001"/>
            <inertia ixx="0.1" iyy="0.1" izz="0.1" ixy="0.0" ixz="0.0" iyz="0.0"/>
        </inertial>
    </link>

    <joint name="joint_rev_x" type="revolute">
        <parent link="wrist_z"/>
        <child link="wrist_rev_x"/>
        <axis xyz="1 0 0"/>
        <limit lower="-6.28" upper="6.28" velocity="0.1" effort="1e9"/>
        <dynamics damping="0.0" friction="0.0"/>
    </joint>

    <link name="wrist_rev_x">
        <inertial>
            <mass value="0.001"/>
            <inertia ixx="0.1" iyy="0.1" izz="0.1" ixy="0.0" ixz="0.0" iyz="0.0"/>
        </inertial>
    </link>

    <joint name="joint_rev_y" type="revolute">
        <parent link="wrist_rev_x"/>
        <child link="wrist_rev_y"/>
        <axis xyz="0 1 0"/>
        <limit lower="-6.28" upper="6.28" velocity="0.1" effort="1e9"/>
        <dynamics damping="0.0" friction="0.0"/>
    </joint>

    <link name="wrist_rev_y">
        <inertial>
            <mass value="0.001"/>
            <inertia ixx="0.1" iyy="0.1" izz="0.1" ixy="0.0" ixz="0.0" iyz="0.0"/>
        </inertial>
    </link>

    <joint name="joint_rev_z" type="revolute">
        <parent link="wrist_rev_y"/>
        <child link="wrist"/>
        <axis xyz="0 0 1"/>
        <limit lower="-6.28" upper="6.28" velocity="0.1" effort="1e9"/>
        <dynamics damping="0.0" friction="0.0"/>
    </joint>

    <link name="wrist">
        <visual>
            <origin rpy="0.0 0.0 0.0" xyz="0.0 0.0 0.0"/>
            <geometry>
                <box size="0.1 0.1 0.1"/>
            </geometry>
        </visual>
        <collision>
            <origin rpy="0.0 -0.6 0.0" xyz="0.0 0.0 0.0"/>
            <geometry>
                <box size="0.1 0.1 0.1"/>
            </geometry>
        </collision>
    </link>

    <joint name="attach" type="fixed">
        <origin xyz="0 0 0" rpy="0 0 0"/>
        <parent link="wrist"/>
        <child link="soft"/>
    </joint>

    <link name="soft">
        <!--        <inertial>-->
        <!--            <mass value="0.001"/>-->
        <!--            <inertia ixx="0.1" iyy="0.1" izz="0.1" ixy="0.0" ixz="0.0" iyz="0.0"/>-->
        <!--        </inertial>-->
        <!--        <visual>-->
        <!--            <origin rpy="0 0 3.1415" xyz="0 0 -0.155"/>-->
        <!--            <geometry>-->
        <!--                <mesh filename="meshes/simplified_textured_v3.obj"/>-->
        <!--            </geometry>-->
        <!--        </visual>-->
        <fem>
            <origin rpy="0 0 3.1415" xyz="0 0 -0.155"/>
            <density value="1000"/>
            <youngs value="3e9"/>
            <poissons value="0.34"/>
            <damping value="0.0"/>
            <attachDistance value="0.05"/>
            <tetmesh filename="simplified_textured_v3.tet"/>
        </fem>
    </link>

</robot>